Workbook

Sheet 液体计算
B1: 液体管道清管器到达时间计算
A2: 序号 | B2: 管线 | C2: 起始站(阀室)下拉选择 | D2: 对应里程(请勿填写) | E2: 到达站(阀室)下拉选择 | F2: 对应里程(请勿填写) | G2: 站间距 (请勿填写) | H2: 单位管容(请勿填写) | I2: 清管器速度 | J2: 排量 | K2: 发出时间 | L2: 预计到达实际 (请勿填写)
A3: 1 | B3: 石兰原油线 | C3: 沙坡头 | D3: =VLOOKUP(C3,石兰线!B3:C15,2,) -> 59 | E3: 红湾站 | F3: =VLOOKUP(E3,石兰线!B3:C15,2,) -> 129.8 | G3: =F3-D3 -> 70.8 | H3: =VLOOKUP(C3,石兰线!B3:F15,4,) -> 154 | I3: =J3/H3 -> 5.474026 | J3: 843 | K3: 46125.733 | L3: =(G3/(J3/H3)/24)+K3 -> 46126.272
A4: 2 | B4: 鄯兰原油线 | C4: 49#阀室 | D4: =VLOOKUP(C4,鄯兰线!B3:C59,2,) -> 1837.9 | E4: 兰州末站 | F4: =VLOOKUP(E4,鄯兰线!B3:C59,2,) -> 1842.35 | G4: =F4-D4 -> 4.45 | H4: =VLOOKUP(C4,鄯兰线!B3:F59,4,) -> 373 | I4: =J4/H4 -> 5.3646113 | J4: 2001 | K4: 45836.375 | L4: =(G4/(J4/H4)/24)+K4 -> 45836.41
A5: 3 | B5: 兰成原油线 | C5: 9#阀室（手动） | D5: =VLOOKUP(C5,兰成线!B3:C59,2,) -> 231.2 | E5: 武山站 | F5: =VLOOKUP(E5,兰成线!B3:E59,2,) -> 258.2 | G5: =F5-D5 -> 27 | H5: =VLOOKUP(C5,兰成线!B3:F59,4,) -> 292.23 | I5: 4.52 | J5: 1233 | K5: 46112.238 | L5: =(G5/(J5/H5)/24)+K5 -> 46112.505
A6: 4 | B6: 乌兰成品油 | C6: 48#阀室 | D6: =VLOOKUP(C6,乌兰线!B3:C69,2,) -> 1809.17 | E6: 兰州末站 | F6: =VLOOKUP(E6,乌兰线!B3:C69,2,) -> 1842.35 | G6: =F6-D6 -> 33.18 | H6: =VLOOKUP(C6,乌兰线!B3:F69,4,) -> 191 | I6: =J6/H6 -> 3.1780105 | J6: 607 | K6: 45761.999 | L6: =(G6/(J6/H6)/24)+K6 -> 45762.434
A7: 5 | B7: 兰成渝 | C7: 临洮站 | D7: =VLOOKUP(C7,兰成渝!B3:C40,2,) -> 93.8 | E7: 陇西站 | F7: =VLOOKUP(E7,兰成渝!B3:C40,2,) -> 196.4 | G7: =F7-D7 -> 102.6 | H7: =VLOOKUP(C7,兰成渝!B4:F70,4,) -> 186 | I7: =J7/H7 -> 4.3010753 | J7: 800 | K7: 45757 | L7: =(G7/(J7/H7)/24)+K7 -> 45757.994
A8: 6 | B8: 兰郑长 | C8: 兰州站 | D8: =VLOOKUP(C8,兰郑长!B3:C14,2,) -> 0 | E8: 定西站 | F8: =VLOOKUP(E8,兰郑长!B3:C13,2,) -> 143.9 | G8: =F8-D8 -> 143.9 | H8: =VLOOKUP(E8,兰郑长!B3:E14,4,) -> 292.23 | I8: =J8/H8 -> 1.7109811 | J8: 500 | K8: 42498.676 | L8: =(G8/(J8/H8)/24)+K8 -> 42502.181
D10: 红湾 | E10: 景泰 | F10: 四墩 | G10: 排量
B11: 石兰脏油 | D11: 19989.2 | E11: 28859.6 | F11: 40070.8 | G11: 670
B12: 石空 | C12: 45738.326 | D12: =D11/$G$11/24+$C$12 -> 45739.569 | E12: =E11/$G$11/24+$C$12 -> 45740.12 | F12: =F11/$G$11/24+$C$12 -> 45740.818
E13: 45740.062 | F13: 45740.739 | G13: 690
E14: 45740.162 | F14: 45740.915 | G14: 620
K15: 45703.5
G17: v速度=Q输量/管容
K18: 46056.66 | L18: 46057.534
C19: 46122.323 | E19: 46122.9 | H19: 503.01 | K19: =(L18-K18)*24 -> 20.983333 | L19: =(K19-43)*60 -> -1321
K21: 95.8 | L21: =K21/K19 -> 4.5655282
E22: =(E19-C19)*24 -> 13.85 | F22: =G5/E22 -> 1.9494585 | K22: 20.99
F23: =G3/E22 -> 5.1119134 | K23: =K21/K22 -> 4.5640781
H24: =G3/H27 -> 5.9746835
H27: 11.85
G29: 0.85 | H29: 60 | I29: =H29*G29 -> 51

Sheet 气体计算
B1: 气体管道清管器到达时间计算
A2: 序号 | B2: 管线 | C2: 起始站(阀室)下拉选择 | D2: 对应里程(请勿填写) | E2: 出站压力Mpa | F2: 到达站(阀室)下拉选择 | G2: 对应里程(请勿填写) | H2: 进站压力Mpa | I2: 平均压力Mpa | J2: 压缩因子 | K2: 管道内径mm | L2: 站间距 (请勿填写) | M2: 输气量104Nm3 | N2: 理论速度Km/h | O2: 发出时间 | P2: 预计到达实际 (请勿填写)
A3: 1 | B3: 西一线 | C3: 山丹压气站 | D3: =VLOOKUP(C3,西一线!B3:D71,3,) -> 1609.35 | E3: 8.94 | F3: 古浪压气站 | G3: =VLOOKUP(F3,西一线!B3:D71,3,) -> 1843.112 | H3: 8.19 | I3: =2*(E3+H3*H3/(E3+H3))/3 -> 8.5704729 | J3: =IF(AND(I3>=2,I3<2.5),(0.9423-0.9532)/0.5*(I3-2)+0.9532,IF(AND(I3>=2.5,I3<3),(0.9315-0.9423)/0.5*(I3-2.5)+0.9423,IF(AND(I3>=3,I3<3.5),(0.9209-0.9315)/0.5*(I3-3)+0.9315,IF(AND(I3>=3.5,I3<4),(0.9105-0.9209)/0.5*(I3-3.5)+0.9105,IF(AND(I3>=4,I3<4.5),(0.9003-0.9105)/0.5*(I3-4)+0.9105,IF(AND(I3>=4.5,I3<5),(0.8903-0.9003)/0.5*(I3-4.5)+0.9003,IF(AND(I3>=5,I3<5.5),(0.8806-0.8903)/0.5*(I3-5)+0.8903,IF(AND(I3>=5.5,I3<6),(0.8713-0.8806)/0.5*(I3-5.5)+0.8806,IF(AND(I3>=6,I3<6.5),(0.8623-0.8713)/0.5*(I3-6)+0.8713,IF(AND(I3>=6.5,I3<7),(0.8537-0.8623)/0.5*(I3-6.5)+0.8623,IF(AND(I3>=7,I3<7.5),(0.8455-0.8537)/0.5*(I3-7)+0.8537,IF(AND(I3>=7.5,I3<8),(0.8377-0.8455)/0.5*(I3-7.5)+0.8455,IF(AND(I3>=8,I3<8.5),(0.8305-0.8377)/0.5*(I3-8)+0.8377,IF(AND(I3>=8.5,I3<9),(0.8228-0.8305)/0.5*(I3-8.5)+0.8305,IF(AND(I3>=9,I3<9.5),(0.8177-0.8228)/0.5*(I3-9)+0.8228,IF(AND(I3>=9.5,I3<9.9),(0.8132-0.8177)/0.5*(I3-9.5)+0.8177,IF(AND(I3>=9.9,I3<10),(0.8128-0.8132)/0.1*(I3-9.9)+0.8132,IF(AND(I3>=10,I3<10.5),(0.8063-0.8128)/0.5*(I3-10)+0.8128,IF(AND(I3>=10.5,I3<11),(0.8003-0.8063)/0.5*(I3-10.5)+0.8063,IF(I3=11,0.8003,"flase")))))))))))))))))))) -> 0.82941472 | K3: =西一线!J3 -> 986.8 | L3: =G3-D3 -> 233.762 | M3: 3200 | N3: =M3*J3/(24*I3*3.14*(K3/2/1000)*(K3/2/1000)) -> 16.880206 | O3: 42952.593 | P3: =(L3/N3/24)+O3 -> 42953.17
A4: 2 | B4: 西二线 | C4: 张掖分输压气站 | D4: =VLOOKUP(C4,西二线!B3:D83,3,) -> 1909.1 | E4: 11.32 | F4: 永昌压气站 | G4: =VLOOKUP(F4,西二线!B3:D88,3,) -> 2055.421 | H4: 10.26 | I4: =2*(E4+H4*H4/(E4+H4))/3 -> 10.798678 | J4: =IF(AND(I4>=2,I4<2.5),(0.9423-0.9532)/0.5*(I4-2)+0.9532,IF(AND(I4>=2.5,I4<3),(0.9315-0.9423)/0.5*(I4-2.5)+0.9423,IF(AND(I4>=3,I4<3.5),(0.9209-0.9315)/0.5*(I4-3)+0.9315,IF(AND(I4>=3.5,I4<4),(0.9105-0.9209)/0.5*(I4-3.5)+0.9105,IF(AND(I4>=4,I4<4.5),(0.9003-0.9105)/0.5*(I4-4)+0.9105,IF(AND(I4>=4.5,I4<5),(0.8903-0.9003)/0.5*(I4-4.5)+0.9003,IF(AND(I4>=5,I4<5.5),(0.8806-0.8903)/0.5*(I4-5)+0.8903,IF(AND(I4>=5.5,I4<6),(0.8713-0.8806)/0.5*(I4-5.5)+0.8806,IF(AND(I4>=6,I4<6.5),(0.8623-0.8713)/0.5*(I4-6)+0.8713,IF(AND(I4>=6.5,I4<7),(0.8537-0.8623)/0.5*(I4-6.5)+0.8623,IF(AND(I4>=7,I4<7.5),(0.8455-0.8537)/0.5*(I4-7)+0.8537,IF(AND(I4>=7.5,I4<8),(0.8377-0.8455)/0.5*(I4-7.5)+0.8455,IF(AND(I4>=8,I4<8.5),(0.8305-0.8377)/0.5*(I4-8)+0.8377,IF(AND(I4>=8.5,I4<9),(0.8228-0.8305)/0.5*(I4-8.5)+0.8305,IF(AND(I4>=9,I4<9.5),(0.8177-0.8228)/0.5*(I4-9)+0.8228,IF(AND(I4>=9.5,I4<9.9),(0.8132-0.8177)/0.5*(I4-9.5)+0.8177,IF(AND(I4>=9.9,I4<10),(0.8128-0.8132)/0.1*(I4-9.9)+0.8132,IF(AND(I4>=10,I4<10.5),(0.8063-0.8128)/0.5*(I4-10)+0.8128,IF(AND(I4>=10.5,I4<11),(0.8003-0.8063)/0.5*(I4-10.5)+0.8063,IF(I4=11,0.8003,"flase")))))))))))))))))))) -> 0.80271587 | K4: =西二线!I3 -> 1182.2 | L4: =G4-D4 -> 146.321 | M4: 5800 | N4: =M4*J4/(24*I4*3.14*(K4/2/1000)*(K4/2/1000)) -> 16.374063 | O4: 43719.683 | P4: =(L4/N4/24)+O4 -> 43720.055
A5: 3 | B5: 西三线 | C5: 永昌压气站 | D5: =VLOOKUP(C5,西三线!B3:D83,3,) -> 1801 | E5: 10.92 | F5: 古浪压气站 | G5: =VLOOKUP(F5,西三线!B3:D83,3,) -> 2004 | H5: 9.76 | I5: =2*(E5+H5*H5/(E5+H5))/3 -> 10.350845 | J5: =IF(AND(I5>=2,I5<2.5),(0.9423-0.9532)/0.5*(I5-2)+0.9532,IF(AND(I5>=2.5,I5<3),(0.9315-0.9423)/0.5*(I5-2.5)+0.9423,IF(AND(I5>=3,I5<3.5),(0.9209-0.9315)/0.5*(I5-3)+0.9315,IF(AND(I5>=3.5,I5<4),(0.9105-0.9209)/0.5*(I5-3.5)+0.9105,IF(AND(I5>=4,I5<4.5),(0.9003-0.9105)/0.5*(I5-4)+0.9105,IF(AND(I5>=4.5,I5<5),(0.8903-0.9003)/0.5*(I5-4.5)+0.9003,IF(AND(I5>=5,I5<5.5),(0.8806-0.8903)/0.5*(I5-5)+0.8903,IF(AND(I5>=5.5,I5<6),(0.8713-0.8806)/0.5*(I5-5.5)+0.8806,IF(AND(I5>=6,I5<6.5),(0.8623-0.8713)/0.5*(I5-6)+0.8713,IF(AND(I5>=6.5,I5<7),(0.8537-0.8623)/0.5*(I5-6.5)+0.8623,IF(AND(I5>=7,I5<7.5),(0.8455-0.8537)/0.5*(I5-7)+0.8537,IF(AND(I5>=7.5,I5<8),(0.8377-0.8455)/0.5*(I5-7.5)+0.8455,IF(AND(I5>=8,I5<8.5),(0.8305-0.8377)/0.5*(I5-8)+0.8377,IF(AND(I5>=8.5,I5<9),(0.8228-0.8305)/0.5*(I5-8.5)+0.8305,IF(AND(I5>=9,I5<9.5),(0.8177-0.8228)/0.5*(I5-9)+0.8228,IF(AND(I5>=9.5,I5<9.9),(0.8132-0.8177)/0.5*(I5-9.5)+0.8177,IF(AND(I5>=9.9,I5<10),(0.8128-0.8132)/0.1*(I5-9.9)+0.8132,IF(AND(I5>=10,I5<10.5),(0.8063-0.8128)/0.5*(I5-10)+0.8128,IF(AND(I5>=10.5,I5<11),(0.8003-0.8063)/0.5*(I5-10.5)+0.8063,IF(I5=11,0.8003,"flase")))))))))))))))))))) -> 0.80823902 | K5: =西三线!I3 -> 1182.2 | L5: =G5-D5 -> 203 | M5: 5538 | N5: =M5*J5/(24*I5*3.14*(K5/2/1000)*(K5/2/1000)) -> 16.423063 | O5: 43718.683 | P5: =(L5/N5/24)+O5 -> 43719.198
A6: 4 | B6: 西四线 | C6: 红柳压气站 | D6: =VLOOKUP(C6,[1]西四线!B2:C49,2,) -> 55.2 | E6: 10.5 | F6: 嘉峪关压气站 | G6: =VLOOKUP(F6,[1]西四线!B2:C49,2,) -> 435.7 | H6: 9.8 | I6: =2*(E6+H6*H6/(E6+H6))/3 -> 10.154023 | J6: =IF(AND(I6>=2,I6<2.5),(0.9423-0.9532)/0.5*(I6-2)+0.9532,IF(AND(I6>=2.5,I6<3),(0.9315-0.9423)/0.5*(I6-2.5)+0.9423,IF(AND(I6>=3,I6<3.5),(0.9209-0.9315)/0.5*(I6-3)+0.9315,IF(AND(I6>=3.5,I6<4),(0.9105-0.9209)/0.5*(I6-3.5)+0.9105,IF(AND(I6>=4,I6<4.5),(0.9003-0.9105)/0.5*(I6-4)+0.9105,IF(AND(I6>=4.5,I6<5),(0.8903-0.9003)/0.5*(I6-4.5)+0.9003,IF(AND(I6>=5,I6<5.5),(0.8806-0.8903)/0.5*(I6-5)+0.8903,IF(AND(I6>=5.5,I6<6),(0.8713-0.8806)/0.5*(I6-5.5)+0.8806,IF(AND(I6>=6,I6<6.5),(0.8623-0.8713)/0.5*(I6-6)+0.8713,IF(AND(I6>=6.5,I6<7),(0.8537-0.8623)/0.5*(I6-6.5)+0.8623,IF(AND(I6>=7,I6<7.5),(0.8455-0.8537)/0.5*(I6-7)+0.8537,IF(AND(I6>=7.5,I6<8),(0.8377-0.8455)/0.5*(I6-7.5)+0.8455,IF(AND(I6>=8,I6<8.5),(0.8305-0.8377)/0.5*(I6-8)+0.8377,IF(AND(I6>=8.5,I6<9),(0.8228-0.8305)/0.5*(I6-8.5)+0.8305,IF(AND(I6>=9,I6<9.5),(0.8177-0.8228)/0.5*(I6-9)+0.8228,IF(AND(I6>=9.5,I6<9.9),(0.8132-0.8177)/0.5*(I6-9.5)+0.8177,IF(AND(I6>=9.9,I6<10),(0.8128-0.8132)/0.1*(I6-9.9)+0.8132,IF(AND(I6>=10,I6<10.5),(0.8063-0.8128)/0.5*(I6-10)+0.8128,IF(AND(I6>=10.5,I6<11),(0.8003-0.8063)/0.5*(I6-10.5)+0.8063,IF(I6=11,0.8003,"flase")))))))))))))))))))) -> 0.8107977 | K6: 1182.2 | L6: =G6-D6 -> 380.5 | M6: 5000 | N6: =M6*J6/(24*I6*3.14*(K6/2/1000)*(K6/2/1000)) -> 15.162875 | O6: 45842.5 | P6: =(L6/N6/24)+O6 -> 45843.546
A7: 5 | B7: 涩宁兰一线 | C7: 湖东压气站 | D7: =VLOOKUP(C7,涩宁兰一线!B3:D43,3,) -> 613.803 | E7: 5.3 | F7: 西宁分输站 | G7: =VLOOKUP(F7,涩宁兰一线!B3:D43,3,) -> 707.747 | H7: 5.2 | I7: =2*(E7+H7*H7/(E7+H7))/3 -> 5.2501587 | J7: =IF(AND(I7>=2,I7<2.5),(0.9423-0.9532)/0.5*(I7-2)+0.9532,IF(AND(I7>=2.5,I7<3),(0.9315-0.9423)/0.5*(I7-2.5)+0.9423,IF(AND(I7>=3,I7<3.5),(0.9209-0.9315)/0.5*(I7-3)+0.9315,IF(AND(I7>=3.5,I7<4),(0.9105-0.9209)/0.5*(I7-3.5)+0.9105,IF(AND(I7>=4,I7<4.5),(0.9003-0.9105)/0.5*(I7-4)+0.9105,IF(AND(I7>=4.5,I7<5),(0.8903-0.9003)/0.5*(I7-4.5)+0.9003,IF(AND(I7>=5,I7<5.5),(0.8806-0.8903)/0.5*(I7-5)+0.8903,IF(AND(I7>=5.5,I7<6),(0.8713-0.8806)/0.5*(I7-5.5)+0.8806,IF(AND(I7>=6,I7<6.5),(0.8623-0.8713)/0.5*(I7-6)+0.8713,IF(AND(I7>=6.5,I7<7),(0.8537-0.8623)/0.5*(I7-6.5)+0.8623,IF(AND(I7>=7,I7<7.5),(0.8455-0.8537)/0.5*(I7-7)+0.8537,IF(AND(I7>=7.5,I7<8),(0.8377-0.8455)/0.5*(I7-7.5)+0.8455,IF(AND(I7>=8,I7<8.5),(0.8305-0.8377)/0.5*(I7-8)+0.8377,IF(AND(I7>=8.5,I7<9),(0.8228-0.8305)/0.5*(I7-8.5)+0.8305,IF(AND(I7>=9,I7<9.5),(0.8177-0.8228)/0.5*(I7-9)+0.8228,IF(AND(I7>=9.5,I7<9.9),(0.8132-0.8177)/0.5*(I7-9.5)+0.8177,IF(AND(I7>=9.9,I7<10),(0.8128-0.8132)/0.1*(I7-9.9)+0.8132,IF(AND(I7>=10,I7<10.5),(0.8063-0.8128)/0.5*(I7-10)+0.8128,IF(AND(I7>=10.5,I7<11),(0.8003-0.8063)/0.5*(I7-10.5)+0.8063,IF(I7=11,0.8003,"flase")))))))))))))))))))) -> 0.88544692 | K7: =涩宁兰一线!J3 -> 645.8 | L7: =G7-D7 -> 93.944 | M7: 500 | N7: =M7*J7/(24*I7*3.14*(K7/2/1000)*(K7/2/1000)) -> 10.732061 | O7: 42607.356 | P7: =(L7/N7/24)+O7 -> 42607.721
A8: 6 | B8: 涩宁兰复线 | C8: 西宁分输站 | D8: =VLOOKUP(C8,涩宁兰复线!B3:D44,3,) -> 729.8 | E8: 5.5 | F8: 35#阀室 | G8: =VLOOKUP(F8,涩宁兰复线!B3:D44,3,) -> 921.4 | H8: 5.2 | I8: =2*(E8+H8*H8/(E8+H8))/3 -> 5.3514019 | J8: =IF(AND(I8>=2,I8<2.5),(0.9423-0.9532)/0.5*(I8-2)+0.9532,IF(AND(I8>=2.5,I8<3),(0.9315-0.9423)/0.5*(I8-2.5)+0.9423,IF(AND(I8>=3,I8<3.5),(0.9209-0.9315)/0.5*(I8-3)+0.9315,IF(AND(I8>=3.5,I8<4),(0.9105-0.9209)/0.5*(I8-3.5)+0.9105,IF(AND(I8>=4,I8<4.5),(0.9003-0.9105)/0.5*(I8-4)+0.9105,IF(AND(I8>=4.5,I8<5),(0.8903-0.9003)/0.5*(I8-4.5)+0.9003,IF(AND(I8>=5,I8<5.5),(0.8806-0.8903)/0.5*(I8-5)+0.8903,IF(AND(I8>=5.5,I8<6),(0.8713-0.8806)/0.5*(I8-5.5)+0.8806,IF(AND(I8>=6,I8<6.5),(0.8623-0.8713)/0.5*(I8-6)+0.8713,IF(AND(I8>=6.5,I8<7),(0.8537-0.8623)/0.5*(I8-6.5)+0.8623,IF(AND(I8>=7,I8<7.5),(0.8455-0.8537)/0.5*(I8-7)+0.8537,IF(AND(I8>=7.5,I8<8),(0.8377-0.8455)/0.5*(I8-7.5)+0.8455,IF(AND(I8>=8,I8<8.5),(0.8305-0.8377)/0.5*(I8-8)+0.8377,IF(AND(I8>=8.5,I8<9),(0.8228-0.8305)/0.5*(I8-8.5)+0.8305,IF(AND(I8>=9,I8<9.5),(0.8177-0.8228)/0.5*(I8-9)+0.8228,IF(AND(I8>=9.5,I8<9.9),(0.8132-0.8177)/0.5*(I8-9.5)+0.8177,IF(AND(I8>=9.9,I8<10),(0.8128-0.8132)/0.1*(I8-9.9)+0.8132,IF(AND(I8>=10,I8<10.5),(0.8063-0.8128)/0.5*(I8-10)+0.8128,IF(AND(I8>=10.5,I8<11),(0.8003-0.8063)/0.5*(I8-10.5)+0.8063,IF(I8=11,0.8003,"flase")))))))))))))))))))) -> 0.8834828 | K8: =涩宁兰复线!J3 -> 645.8 | L8: =G8-D8 -> 191.6 | M8: 430 | N8: =M8*J8/(24*I8*3.14*(K8/2/1000)*(K8/2/1000)) -> 9.0348721 | O8: 42623.625 | P8: =(L8/N8/24)+O8 -> 42624.509
B11: 气体管道清管器到达时间计算（分输支线）
A12: 序号 | B12: 管线 | C12: 起始站(阀室)下拉选择 | D12: 对应里程(请勿填写) | E12: 出站压力Mpa | F12: 到达站(阀室) | G12: 对应里程 | H12: 进站压力Mpa | I12: 平均压力Mpa | J12: 压缩因子 | K12: 管道内径mm | L12: 站间距 | M12: 输气量104Nm3 | N12: 理论速度Km/h | O12: 发出时间 | P12: 预计到达实际 (请勿填写)
C13: 古浪压气站 | D13: 2258.1 | E13: 10.71 | F13: 中卫压气站 | G13: =D13+150 -> 2408.1 | H13: 9.65 | I13: =2*(E13+H13*H13/(E13+H13))/3 -> 10.189198 | J13: =IF(AND(I13>=2,I13<2.5),(0.9423-0.9532)/0.5*(I13-2)+0.9532,IF(AND(I13>=2.5,I13<3),(0.9315-0.9423)/0.5*(I13-2.5)+0.9423,IF(AND(I13>=3,I13<3.5),(0.9209-0.9315)/0.5*(I13-3)+0.9315,IF(AND(I13>=3.5,I13<4),(0.9105-0.9209)/0.5*(I13-3.5)+0.9105,IF(AND(I13>=4,I13<4.5),(0.9003-0.9105)/0.5*(I13-4)+0.9105,IF(AND(I13>=4.5,I13<5),(0.8903-0.9003)/0.5*(I13-4.5)+0.9003,IF(AND(I13>=5,I13<5.5),(0.8806-0.8903)/0.5*(I13-5)+0.8903,IF(AND(I13>=5.5,I13<6),(0.8713-0.8806)/0.5*(I13-5.5)+0.8806,IF(AND(I13>=6,I13<6.5),(0.8623-0.8713)/0.5*(I13-6)+0.8713,IF(AND(I13>=6.5,I13<7),(0.8537-0.8623)/0.5*(I13-6.5)+0.8623,IF(AND(I13>=7,I13<7.5),(0.8455-0.8537)/0.5*(I13-7)+0.8537,IF(AND(I13>=7.5,I13<8),(0.8377-0.8455)/0.5*(I13-7.5)+0.8455,IF(AND(I13>=8,I13<8.5),(0.8305-0.8377)/0.5*(I13-8)+0.8377,IF(AND(I13>=8.5,I13<9),(0.8228-0.8305)/0.5*(I13-8.5)+0.8305,IF(AND(I13>=9,I13<9.5),(0.8177-0.8228)/0.5*(I13-9)+0.8228,IF(AND(I13>=9.5,I13<9.9),(0.8132-0.8177)/0.5*(I13-9.5)+0.8177,IF(AND(I13>=9.9,I13<10),(0.8128-0.8132)/0.1*(I13-9.9)+0.8132,IF(AND(I13>=10,I13<10.5),(0.8063-0.8128)/0.5*(I13-10)+0.8128,IF(AND(I13>=10.5,I13<11),(0.8003-0.8063)/0.5*(I13-10.5)+0.8063,IF(I13=11,0.8003,"flase")))))))))))))))))))) -> 0.81034043 | K13: 1182.2 | L13: =G13-D13 -> 150 | M13: 6995 | N13: =M13*J13/(24*I13*3.14*(K13/2/1000)*(K13/2/1000)) -> 21.12771 | O13: 43706.497 | P13: =(L13/N13/24)+O13 -> 43706.792
A14: 1 | B14: 西二线金昌分输支线 | C14: 61#阀室 | D14: =VLOOKUP(C14,西二线!B10:D90,3,) -> 2108.25 | E14: 10.39 | F14: 金昌分输站 （金昌末站） | G14: 2156.09 | H14: 10.64 | I14: =2*(E14+H14*H14/(E14+H14))/3 -> 10.515495 | J14: =IF(AND(I14>=2,I14<2.5),(0.9423-0.9532)/0.5*(I14-2)+0.9532,IF(AND(I14>=2.5,I14<3),(0.9315-0.9423)/0.5*(I14-2.5)+0.9423,IF(AND(I14>=3,I14<3.5),(0.9209-0.9315)/0.5*(I14-3)+0.9315,IF(AND(I14>=3.5,I14<4),(0.9105-0.9209)/0.5*(I14-3.5)+0.9105,IF(AND(I14>=4,I14<4.5),(0.9003-0.9105)/0.5*(I14-4)+0.9105,IF(AND(I14>=4.5,I14<5),(0.8903-0.9003)/0.5*(I14-4.5)+0.9003,IF(AND(I14>=5,I14<5.5),(0.8806-0.8903)/0.5*(I14-5)+0.8903,IF(AND(I14>=5.5,I14<6),(0.8713-0.8806)/0.5*(I14-5.5)+0.8806,IF(AND(I14>=6,I14<6.5),(0.8623-0.8713)/0.5*(I14-6)+0.8713,IF(AND(I14>=6.5,I14<7),(0.8537-0.8623)/0.5*(I14-6.5)+0.8623,IF(AND(I14>=7,I14<7.5),(0.8455-0.8537)/0.5*(I14-7)+0.8537,IF(AND(I14>=7.5,I14<8),(0.8377-0.8455)/0.5*(I14-7.5)+0.8455,IF(AND(I14>=8,I14<8.5),(0.8305-0.8377)/0.5*(I14-8)+0.8377,IF(AND(I14>=8.5,I14<9),(0.8228-0.8305)/0.5*(I14-8.5)+0.8305,IF(AND(I14>=9,I14<9.5),(0.8177-0.8228)/0.5*(I14-9)+0.8228,IF(AND(I14>=9.5,I14<9.9),(0.8132-0.8177)/0.5*(I14-9.5)+0.8177,IF(AND(I14>=9.9,I14<10),(0.8128-0.8132)/0.1*(I14-9.9)+0.8132,IF(AND(I14>=10,I14<10.5),(0.8063-0.8128)/0.5*(I14-10)+0.8128,IF(AND(I14>=10.5,I14<11),(0.8003-0.8063)/0.5*(I14-10.5)+0.8063,IF(I14=11,0.8003,"flase")))))))))))))))))))) -> 0.80611406 | K14: 157.1 | L14: =G14-D14 -> 47.84 | M14: 12.8 | N14: =M14*J14/(24*I14*3.14*(K14/2/1000)*(K14/2/1000)) -> 2.1102964 | O14: 44431.472 | P14: =(L14/N14/24)+O14 -> 44432.417 | Q14: 金昌分输
K15: 管径-壁厚*2 | L15: 管道科提供数据 | M15: 看站控机

Sheet 石兰线
A1: 乌鄯原油管道清管器跟踪时间记录表
A2: 序号 | B2: 场站/阀室 | C2: 里程数(km) | D2: 与上一测试桩相对距离（公里） | E2: 单位管容（m³） | F2: 对应管容（m³）
A3: 1 | B3: 沙坡头 | C3: 59 | D3: 0 | E3: 154 | F3: 0
A4: 2 | B4: 2#阀室(手动) | C4: 86.7 | D4: =C4-C3 -> 27.7 | E4: 154 | F4: =D4*E4 -> 4265.8
A5: 3 | B5: 3#阀室(手动) | C5: 105.2 | D5: =C5-C4 -> 18.5 | E5: 154 | F5: =D5*E5 -> 2849
A6: 4 | B6: 红湾站 | C6: 129.8 | D6: =C6-C5 -> 24.6 | E6: 154 | F6: =D6*E6 -> 3788.4
A7: 5 | B7: 4#阀室（手动) | C7: 158.6 | D7: =C7-C6 -> 28.8 | E7: 154 | F7: =D7*E7 -> 4435.2
A8: 6 | B8: 景泰站 | C8: 187.4 | D8: =C8-C7 -> 28.8 | E8: 154 | F8: =D8*E8 -> 4435.2
A9: 7 | B9: 5#阀室（手动、高点） | C9: 218.1 | D9: =C9-C8 -> 30.7 | E9: 154 | F9: =D9*E9 -> 4727.8
A10: 8 | B10: 6#阀室(RTU) | C10: 248 | D10: =C10-C9 -> 29.9 | E10: 154 | F10: =D10*E10 -> 4604.6
A11: 9 | B11: 四墩站 | C11: 260.2 | D11: =C11-C10 -> 12.2 | E11: 154 | F11: =D11*E11 -> 1878.8
A12: 10 | B12: 7#阀室(手动） | C12: 279.9 | D12: =C12-C11 -> 19.7 | E12: 154 | F12: =D12*E12 -> 3033.8
A13: 11 | B13: 8#阀室（手动） | C13: 298.5 | D13: =C13-C12 -> 18.6 | E13: 154 | F13: =D13*E13 -> 2864.4
A14: 12 | B14: 9#阀室（RTU) | C14: 321.8 | D14: =C14-C13 -> 23.3 | E14: 154 | F14: =D14*E14 -> 3588.2
A15: 13 | B15: 兰州站 | C15: 324.3 | D15: =C15-C14 -> 2.5 | E15: 154 | F15: =D15*E15 -> 385

Sheet 鄯兰线
A1: 鄯兰原油管道清管器跟踪时间记录表
A2: 序号 | B2: 场站/阀室 | C2: 里程数(km) | D2: 与上一测试桩相对距离（公里） | E2: 单位管容（m³） | F2: 对应管容（m³）
A3: 1 | B3: 鄯善站 | C3: 293.397 | D3: 0 | E3: 491 | F3: =D3*E3 -> 0
A4: 2 | B4: 9#阀室（手动） | C4: 330.167 | D4: =C4-C3 -> 36.77 | E4: 491 | F4: =D4*E4 -> 18054.07
A5: 3 | B5: 10#阀室（手动） | C5: 366.197 | D5: =C5-C4 -> 36.03 | E5: 491 | F5: =D5*E5 -> 17690.73
A6: 4 | B6: 11#阀室（RTU、流量计) | C6: 398.913 | D6: =C6-C5 -> 32.716 | E6: 491 | F6: =D6*E6 -> 16063.556
A7: 5 | B7: 12#阀室(手动） | C7: 433.347 | D7: =C7-C6 -> 34.434 | E7: 491 | F7: =D7*E7 -> 16907.094
A8: 6 | B8: 13#阀室（手动） | C8: 470.369 | D8: =C8-C7 -> 37.022 | E8: 491 | F8: =D8*E8 -> 18177.802
A9: 7 | B9: 14#阀室（RTU) | C9: 501.377 | D9: =C9-C8 -> 31.008 | E9: 491 | F9: =D9*E9 -> 15224.928
A10: 8 | B10: 四堡站 | C10: 534.226 | D10: =C10-C9 -> 32.849 | E10: 491 | F10: =D10*E10 -> 16128.859
A11: 9 | B11: 15#阀室(RTU、分输) | C11: 555.226 | D11: =C11-C10 -> 21 | E11: 491 | F11: =D11*E11 -> 10311
A12: 10 | B12: 15A阀室(手动） | C12: 575.226 | D12: =C12-C11 -> 20 | E12: 491 | F12: =D12*E12 -> 9820
A13: 11 | B13: 16#阀室（手动） | C13: 596.226 | D13: =C13-C12 -> 21 | E13: 491 | F13: =D13*E13 -> 10311
A14: 12 | B14: 17#阀室（手动、单向） | C14: 629.506 | D14: =C14-C13 -> 33.28 | E14: 491 | F14: =D14*E14 -> 16340.48
A15: 13 | B15: 翠岭站 | C15: 660.506 | D15: =C15-C14 -> 31 | E15: 491 | F15: =D15*E15 -> 15221
... A17: 15 | B17: 河西站 | C17: 725.506 | D17: =C17-C16 -> 32 | E17: 491 | F17: =D17*E17 -> 15712
A18: 16 | B18: 19#阀室 | C18: 756.729 | D18: 31.223 | E18: 491 | F18: =D18*E18 -> 15330.493
A19: 17 | B19: 20#阀室 | C19: 787.568 | D19: 31 | E19: 491 | F19: =D19*E19 -> 15221
A20: 18 | B20: 2#高点 | C20: 807.339 | D20: 19 | E20: 491 | F20: =D20*E20 -> 9329
A21: 19 | B21: 21#阀室 | C21: 819.306 | D21: 13 | E21: 491 | F21: =D21*E21 -> 6383
A22: 20 | B22: 22#阀室 | C22: 848.306 | D22: 30 | E22: 491 | F22: =D22*E22 -> 14730
A23: 21 | B23: 23#阀室 | C23: 879.779 | D23: 31 | E23: 491 | F23: =D23*E23 -> 15221
A24: 22 | B24: 24#阀室 | C24: 909.779 | D24: 30 | E24: 491 | F24: =D24*E24 -> 14730
A25: 23 | B25: 瓜州站 | C25: 943.779 | D25: 37 | E25: 491 | F25: =D25*E25 -> 18167
A26: 24 | B26: 25#阀室 | C26: 974.354 | D26: 29.975 | E26: 491 | F26: =D26*E26 -> 14717.725
A27: 25 | B27: 26#阀室 | C27: 1008.604 | D27: 34.25 | E27: 491 | F27: =D27*E27 -> 16816.75
A28: 26 | B28: 玉门站 | C28: 1044.704 | D28: 36.1 | E28: 491 | F28: =D28*E28 -> 17725.1
A29: 27 | B29: 27#阀室 | C29: 1062.804 | D29: 18.1 | E29: 491 | F29: =D29*E29 -> 8887.1
... A55: 53 | B55: 46#阀室 | C55: 1754.6 | D55: 43.69 | E55: 373 | F55: =D55*E55 -> 16296.37
A56: 54 | B56: 47#阀室 | C56: 1781 | D56: =C56-C55 -> 26.4 | E56: 373 | F56: =D56*E56 -> 9847.2
A57: 55 | B57: 48#阀室 | C57: 1809.17 | D57: =C57-C56 -> 28.17 | E57: 373 | F57: =D57*E57 -> 10507.41
A58: 56 | B58: 49#阀室 | C58: 1837.9 | D58: =C58-C57 -> 28.73 | E58: 373 | F58: =D58*E58 -> 10716.29
A59: 57 | B59: 兰州末站 | C59: 1842.35 | E59: 373 | F59: =D59*E59 -> 0
B60: 46A阀室 | C60: 1794+300M

Sheet 兰成线
A1: 轮库原油复线管道清管器跟踪时间记录表
A2: 序号 | B2: 位置 | C2: 里程位置(km) | D2: 与上一测试桩相对距离（公里） | E2: 单位管容 | F2: 对应管容（m³）
A3: 1 | B3: 兰州 | C3: 0 | D3: 0 | E3: 292.23 | F3: =D3*E3 -> 0
A4: 2 | B4: 1#阀室（单向） | C4: 5.23 | D4: =C4-C3 -> 5.23 | E4: 292.23 | F4: =D4*E4 -> 1528.3629
A5: 3 | B5: 2#阀室（手动） | C5: 32.5 | D5: =C5-C4 -> 27.27 | E5: 292.23 | F5: =D5*E5 -> 7969.1121
A6: 4 | B6: 3#阀室（RTU） | C6: 63.7 | D6: =C6-C5 -> 31.2 | E6: 292.23 | F6: =D6*E6 -> 9117.576
A7: 5 | B7: 临洮站 | C7: 95.8 | D7: =C7-C6 -> 32.1 | E7: 292.23 | F7: =D7*E7 -> 9380.583
A8: 6 | B8: 4#阀室（RTU） | C8: 115.7 | D8: =C8-C7 -> 19.9 | E8: 292.23 | F8: =D8*E8 -> 5815.377
A9: 7 | B9: 5#阀室（单向） | C9: 136.2 | D9: =C9-C8 -> 20.5 | E9: 292.23 | F9: =D9*E9 -> 5990.715
A10: 8 | B10: 6#阀室（RTU） | C10: 155.2 | D10: =C10-C9 -> 19 | E10: 292.23 | F10: =D10*E10 -> 5552.37
A11: 9 | B11: 陇西站 | C11: 176.9 | D11: =C11-C10 -> 21.7 | E11: 292.23 | F11: =D11*E11 -> 6341.391
A12: 10 | B12: 7#阀室（单向） | C12: 183 | D12: =C12-C11 -> 6.1 | E12: 292.23 | F12: =D12*E12 -> 1782.603
A13: 11 | B13: 8#阀室（手动） | C13: 204 | D13: =C13-C12 -> 21 | E13: 292.23 | F13: =D13*E13 -> 6136.83
A14: 12 | B14: 9#阀室（手动） | C14: 231.2 | D14: =C14-C13 -> 27.2 | E14: 292.23 | F14: =D14*E14 -> 7948.656
A15: 13 | B15: 武山站 | C15: 258.2 | D15: =C15-C14 -> 27 | E15: 292.23 | F15: =D15*E15 -> 7890.21
... A30: 28 | B30: 广元站 | C30: 576 | D30: =C30-C29 -> 29.5 | E30: 292.23 | F30: =D30*E30 -> 8620.785

Sheet 乌兰线
A1: 乌兰成品油管道清管器跟踪时间记录表
A2: 序号 | B2: 场站/阀室 | C2: 里程数(km) | D2: 与上一测试桩相对距离（公里） | E2: 单位管容（m³） | F2: 对应管容（m³）
A3: 1 | B3: 乌首站 | C3: 0 | E3: 233 | F3: 0
A4: 2 | B4: 1#阀室(RTU) | C4: 33.152 | D4: =C4-C3 -> 33.152 | E4: 233 | F4: =D4*E4 -> 7724.416
A5: 3 | B5: 2#（手动） | C5: 74.341 | D5: =C5-C4 -> 41.189 | E5: 233 | F5: =D5*E5 -> 9597.037
A6: 4 | B6: 达坂城RTU（3#阀室） | C6: 111.47 | D6: =C6-C5 -> 37.129 | E6: 233 | F6: =D6*E6 -> 8651.057
A7: 5 | B7: 1#高点 | C7: 118.429 | D7: =C7-C6 -> 6.959 | E7: 233 | F7: =D7*E7 -> 1621.447
A8: 6 | B8: 4#阀室（RTU) | C8: 145.13 | D8: =C8-C7 -> 26.701 | E8: 233 | F8: =D8*E8 -> 6221.333
A9: 7 | B9: 5#手动、分输、流量 | C9: 174.064 | D9: =C9-C8 -> 28.934 | E9: 233 | F9: =D9*E9 -> 6741.622
A10: 8 | B10: 6#阀室(RTU) | C10: 210.62 | D10: =C10-C9 -> 36.556 | E10: 233 | F10: =D10*E10 -> 8517.548
A11: 9 | B11: 7#阀室(RTU) | C11: 238.122 | D11: =C11-C10 -> 27.502 | E11: 233 | F11: =D11*E11 -> 6407.966
A12: 10 | B12: 8#阀室(手动） | C12: 266.333 | D12: =C12-C11 -> 28.211 | E12: 233 | F12: =D12*E12 -> 6573.163
A13: 11 | B13: 鄯善站 | C13: 293.397 | D13: =C13-C12 -> 27.064 | E13: 233 | F13: =D13*E13 -> 6305.912
A14: 12 | B14: 9#阀室（手动） | C14: 330.167 | D14: =C14-C13 -> 36.77 | E14: 233 | F14: =D14*E14 -> 8567.41
A15: 13 | B15: 10#阀室（手动） | C15: 366.197 | D15: =C15-C14 -> 36.03 | E15: 233 | F15: =D15*E15 -> 8394.99
... A27: 25 | B27: 河西站 | C27: 725.506 | D27: =C27-C26 -> 32 | E27: 233 | F27: =D27*E27 -> 7456
A28: 26 | B28: 19#阀室 | C28: 756.729 | D28: 31.223 | E28: 233 | F28: =D28*E28 -> 7274.959
A29: 27 | B29: 20#阀室 | C29: 787.568 | D29: 31 | E29: 233 | F29: =D29*E29 -> 7223
A30: 28 | B30: 2#高点 | C30: 807.339 | D30: 19 | E30: 233 | F30: =D30*E30 -> 4427
A31: 29 | B31: 21#阀室 | C31: 819.306 | D31: 13 | E31: 233 | F31: =D31*E31 -> 3029
A32: 30 | B32: 22#阀室 | C32: 848.306 | D32: 30 | E32: 233 | F32: =D32*E32 -> 6990
A33: 31 | B33: 23#阀室 | C33: 879.779 | D33: 31 | E33: 233 | F33: =D33*E33 -> 7223
A34: 32 | B34: 24#阀室 | C34: 909.779 | D34: 30 | E34: 233 | F34: =D34*E34 -> 6990
A35: 33 | B35: 瓜州站 | C35: 943.779 | D35: 37 | E35: 233 | F35: =D35*E35 -> 8621
A36: 34 | B36: 25#阀室 | C36: 974.354 | D36: 29.975 | E36: 233 | F36: =D36*E36 -> 6984.175
A37: 35 | B37: 26#阀室 | C37: 1008.604 | D37: 34.25 | E37: 233 | F37: =D37*E37 -> 7980.25
A38: 36 | B38: 玉门站 | C38: 1044.704 | D38: 36.1 | E38: 233 | F38: =D38*E38 -> 8411.3
A39: 37 | B39: 27#阀室 | C39: 1062.804 | D39: 18.1 | E39: 233 | F39: =D39*E39 -> 4217.3
... A65: 63 | B65: 46#阀室 | C65: 1754.6 | D65: 43.69 | E65: 191 | F65: =D65*E65 -> 8344.79
A66: 64 | B66: 47#阀室 | C66: 1781 | D66: =C66-C65 -> 26.4 | E66: 191 | F66: =D66*E66 -> 5042.4
A67: 65 | B67: 48#阀室 | C67: 1809.17 | D67: =C67-C66 -> 28.17 | E67: 191 | F67: =D67*E67 -> 5380.47
A68: 66 | B68: 49#阀室 | C68: 1837.9 | D68: =C68-C67 -> 28.73 | E68: 191 | F68: =D68*E68 -> 5487.43
A69: 67 | B69: 兰州末站 | C69: 1842.35 | E69: 191 | F69: =D69*E69 -> 0 | H69: =C63-C62 -> 12.421
H70: =C64-C63 -> 17.559
H71: =C65-C64 -> 27.9
D74: =C63-C62 -> 12.421
D75: =C64-C63 -> 17.559

Sheet 兰成渝
A1: 兰成渝线沿线阀室里程
A2: 序号 | B2: 位置 | C2: 里程位置(km) | D2: 与上一测试桩相对距离（公里） | E2: 单位管容 | F2: 对应管容（m³）
A3: 1 | B3: 兰州站 | C3: 0 | D3: 0 | E3: 186
A4: 2 | B4: 孟家山阀室 | C4: 4.6 | D4: =C4-C3 -> 4.6 | E4: 186
A5: 3 | B5: 马家山阀室 | C5: 7.7 | D5: =C5-C4 -> 3.1 | E5: 186
A6: 4 | B6: 关山高点 | C6: 13.1 | D6: =C6-C5 -> 5.4 | E6: 186
A7: 5 | B7: 何家湾阀室 | C7: 36.2 | D7: =C7-C6 -> 23.1 | E7: 186
A8: 6 | B8: 水泉阀室 | C8: 68.5 | D8: =C8-C7 -> 32.3 | E8: 186
A9: 7 | B9: 临洮站 | C9: 93.8 | D9: =C9-C8 -> 25.3 | E9: 186
A10: 8 | B10: 东十里铺阀室 | C10: 103.8 | D10: =C10-C9 -> 10 | E10: 186
A11: 9 | B11: 庆平阀室 | C11: 133.3 | D11: =C11-C10 -> 29.5 | E11: 186
A12: 10 | B12: 营盘梁阀室 | C12: 140.4 | D12: =C12-C11 -> 7.1 | E12: 186
A13: 11 | B13: 渭源北阀室 | C13: 146.7 | D13: =C13-C12 -> 6.3 | E13: 186
A14: 12 | B14: 三十里铺阀室 | C14: 172.2 | D14: =C14-C13 -> 25.5 | E14: 186
A15: 13 | B15: 陇西站 | C15: 196.4 | D15: =C15-C14 -> 24.2 | E15: 186
... A40: 38 | B40: 广元站 | C40: 589 | D40: =C40-C39 -> 25 | E40: 186

Sheet 兰郑长
A1: 克-703-独线沿线阀室里程
A2: 序号 | B2: 位置 | C2: 里程位置(km) | D2: 与上一测试桩相对距离（公里） | E2: 单位管容 | F2: 对应管容（m³）
A3: 1 | B3: 兰州站 | C3: 0 | D3: 0 | E3: 292.23
A4: 2 | B4: 1#阀室（单向） | C4: 7.4 | D4: =C4-C3 -> 7.4 | E4: 292.23
A5: 3 | B5: 关山站 | C5: 19.17 | D5: =C5-C4 -> 11.77 | E5: 292.23
A6: 4 | B6: 2#阀室 | C6: 26.2 | D6: =C6-C5 -> 7.03 | E6: 292.23
A7: 5 | B7: 3#阀室（RTU） | C7: 76.3 | D7: =C7-C6 -> 50.1 | E7: 292.23
A8: 6 | B8: 4#阀室 | C8: 110.4 | D8: =C8-C7 -> 34.1 | E8: 292.23
A9: 7 | B9: 5#阀室 | C9: 124 | D9: =C9-C8 -> 13.6 | E9: 292.23
A10: 8 | B10: 定西站 | C10: 143.9 | D10: =C10-C9 -> 19.9 | E10: 292.23
A11: 9 | B11: 6#阀室 | C11: 162.3 | D11: =C11-C10 -> 18.4 | E11: 292.23
A12: 10 | B12: 7#阀室（RTU） | C12: 189.2 | D12: =C12-C11 -> 26.9 | E12: 292.23
A13: 11 | B13: 8#阀室（RTU） | C13: 214.1 | D13: =C13-C12 -> 24.9 | E13: 292.23
A14: 12 | B14: 9#阀室 | C14: 244.6 | D14: =C14-C13 -> 30.5 | E14: 292.23
A15: 13 | B15: 10#阀室 | C15: 268.3 | D15: =C15-C14 -> 23.7 | E15: 292.23
... A20: 18 | B20: 固关站 | C20: 384.6 | D20: =C20-C19 -> 22.6 | E20: 292.23

Sheet 西一线
A1: 西一线站场、阀室与里程桩对应表
A2: 序号 | B2: 站场/阀室名称 | C2: 桩号（阴保桩）前一阀室后一桩号-本阀室前一桩号 | D2: 里程/km | E2: 所在行政区域 | F2: 所属作业区 | G2: 备注 | H2: 外径 | I2: 壁厚 | J2: 内径 | K2: 管容
A3: 1 | B3: 轮南压气站 | D3: 0 | E3: 库尔勒市（地区） | F3: 轮南作业区 | H3: 1016 | I3: 14.6 | J3: 986.8 | K3: 764
A4: 2 | B4: 1#阀室 | C4: 0#-32#桩 | D4: 32 | E4: 库尔勒市（地区） | F4: 轮南作业区 | G4: 轮南压气站-1#阀室测试桩
A5: 3 | B5: 2#阀室 | C5: 33#-64#桩 | D5: 64 | E5: 库尔勒市（地区） | F5: 轮南作业区 | G5: 1#-2#阀室测试桩
A6: 4 | B6: 3#阀室 | C6: 65#-96#桩 | D6: 96 | E6: 库尔勒市（地区） | F6: 轮南作业区 | G6: 2#-3#阀室测试桩
A7: 5 | B7: 4#阀室 | C7: 97#-129# | D7: 129.5 | E7: 库尔勒市29团 | F7: 库尔勒作业区
A8: 6 | B8: 5#阀室 | C8: 130#-160# | D8: 160.16 | E8: 库尔勒市上户镇 | F8: 库尔勒作业区
A9: 7 | B9: 孔雀河压气站 | C9: 161#-182# | D9: 182.3 | E9: 库尔勒市龙山 | F9: 库尔勒作业区
A10: 8 | B10: 6#阀室 | C10: 183#-206# | D10: 206.95 | E10: 库尔勒塔什店镇 | F10: 库尔勒作业区
A11: 9 | B11: 7#阀室 | C11: 207#-239# | D11: 239.7 | E11: 库尔勒博湖县博斯腾湖乡 | F11: 库尔勒作业区
A12: 10 | B12: 8#阀室 | C12: 240#-263# | D12: 263.6 | E12: 库尔勒博湖县博斯腾湖乡 | F12: 库尔勒作业区
A13: 11 | B13: 9#阀室 | C13: 264#-291# | D13: 290.6 | E13: 库尔勒市和硕县 | F13: 库米什作业区 | G13: 8#-9#阀室测试桩
A14: 12 | B14: 四道班压气站 | C14: 292#-315# | D14: 313.6 | E14: 库尔勒市和硕县 | F14: 库米什作业区 | G14: 9#-四道班压气站测试桩
A15: 13 | B15: 10#阀室 | C15: 316#-347# | D15: 344 | E15: 吐鲁番地区托克逊县 | F15: 库米什作业区
A16: 14 | B16: 11#阀室 | C16: 347#-376# | D16: 373 | E16: 吐鲁番地区托克逊县 | F16: 库米什作业区
A17: 15 | B17: 12#阀室 | C17: 376#-404# | D17: 401 | E17: 吐鲁番地区托克逊县 | F17: 库米什作业区
A18: 16 | B18: 13#阀室 | C18: 405#-436# | D18: 436.711 | E18: 吐鲁番艾丁湖乡 | F18: 连木沁作业区
A19: 17 | B19: 14#阀室 | C19: 437#-465# | D19: 465.711 | E19: 吐鲁番艾丁湖乡 | F19: 连木沁作业区
A20: 18 | B20: 鄯善压气站 | C20: 466#-497# | D20: 497 | E20: 鄯善县迪坎乡 | F20: 连木沁作业区
A21: 19 | B21: 15#阀室 | C21: 498#-527# | D21: 527.5 | E21: 鄯善县迪坎乡 | F21: 连木沁作业区
A22: 20 | B22: 16#阀室 | C22: 528#-554# | D22: 554 | E22: 鄯善县迪坎乡 | F22: 连木沁作业区
A23: 21 | B23: 17#阀室 | C23: 555#-584# | D23: 584.2 | E23: 吐鲁番 | F23: 了墩作业区
A24: 22 | B24: 18#阀室 | C24: 585#-615# | D24: 614.9 | E24: 吐鲁番 | F24: 了墩作业区
A25: 23 | B25: 19#阀室 | C25: 616#-645# | D25: 645.6 | E25: 吐鲁番 | F25: 了墩作业区
A26: 24 | B26: 哈密压气站 | C26: 646#-662# | D26: 661.6 | E26: 吐鲁番市 | F26: 了墩作业区
... A35: 33 | B35: 28#阀室 | C35: 899#-928# | D35: 928 | E35: 哈密市 | F35: 烟墩作业区
A36: 34 | B36: 红柳压气站 | C36: 929#-959# | D36: 959 | E36: 酒泉市 | F36: 红柳作业区 | G36: 940#-红柳压气站测试桩
A37: 35 | B37: 29#阀室 | C37: 960#-992# | D37: 992 | E37: 酒泉市 | F37: 红柳作业区 | G37: 红柳压气站-29#阀室测试桩
A38: 36 | B38: 30#阀室 | C38: 993#-1022# | D38: 1022 | E38: 酒泉市 | F38: 红柳作业区 | G38: 29#阀室-30#阀室测试桩
A39: 37 | B39: 31#阀室 | C39: 1023#-1055# | D39: 1055 | E39: 酒泉市 | F39: 红柳作业区 | G39: 30#阀室-31#阀室测试桩
A40: 38 | B40: 32#阀室 | C40: 1056#-1084# | D40: 1085 | E40: 甘肃省酒泉市瓜州县 | F40: 瓜州作业区 | G40: 31#阀室-32#阀室测试桩
A41: 39 | B41: 柳园压气站 | C41: 1085#-1116# | D41: 1117 | E41: 甘肃省酒泉市瓜州县 | F41: 瓜州作业区 | G41: 32#阀室-柳园压气站
A42: 40 | B42: 33#阀室 | C42: 1117#-1141# | D42: 1142 | E42: 甘肃省酒泉市瓜州县布隆吉乡 | F42: 瓜州作业区 | G42: 柳园压气站-33#阀室测试桩
A43: 41 | B43: 34#阀室 | C43: 1142#-1170# | D43: 1170 | E43: 玉门市柳河乡戈壁 | F43: 玉门作业区 | G43: 33#-34#阀室测试桩
A44: 42 | B44: 35#阀室 | C44: 1171#-1191# | D44: 1190 | E44: 玉门市玉门镇戈壁 | F44: 玉门作业区 | G44: 34#-35#阀室测试桩
A45: 43 | B45: 36#阀室 | C45: 1192#-1219# | D45: 1217 | E45: 玉门市赤金镇戈壁 | F45: 玉门作业区 | G45: 35#-36#阀室测试桩
A46: 44 | B46: 37#阀室 | C46: 1220#-1243# | D46: 1240 | E46: 玉门市赤金镇东湖村戈壁 | F46: 玉门作业区 | G46: 36#-37#阀室测试桩
A47: 45 | B47: 玉门压气站 | C47: 1244#-1270# | D47: 1266 | E47: 玉门市清泉村戈壁 | F47: 玉门作业区 | G47: 37#-玉门压气站
... A57: 55 | B57: 46#阀室 | C57: 1510#-1534# | D57: 1534.6 | E57: 张掖市 | F57: 张掖作业区 | G57: 45#阀室-46#阀室
...

Sheet 西二线
A1: 西二线站场、阀室与里程桩对应表
A2: 序号 | B2: 站场/阀室名称 | C2: 桩号（阴保桩）前一阀室后一桩号-本阀室前一桩号 | D2: 里程/km | E2: 所在行政区域 | F2: 所属作业区 | G2: 外径 | H2: 壁厚 | I2: 内径 | J2: 管容
A3: 1 | B3: 霍尔果斯首站 | C3: 0 | D3: 0 | E3: 霍城县 | F3: 霍尔果斯作业区 | G3: 1219 | H3: 18.4 | I3: 1182.2 | J3: =1000*3.14*(I3/2/1000)*(I3/2/1000) -> 1097.1135
A4: 2 | B4: 1#阀室 | C4: 0#-30# | D4: 30 | E4: 霍城县 | F4: 霍尔果斯作业区
A5: 3 | B5: 2#阀室 | C5: 31#-46# | D5: 46 | E5: 霍城县 | F5: 霍尔果斯作业区
A6: 4 | B6: 3#阀室 | C6: 47#-75# | D6: 75 | E6: 霍城县 | F6: 霍尔果斯作业区
A7: 5 | B7: 4#阀室 | C7: 76#-104# | D7: 106 | E7: 博州 | F7: 阿拉山口作业区
A8: 6 | B8: 5#阀室 | C8: 105#-139# | D8: 142 | E8: 博州 | F8: 阿拉山口作业区
A9: 7 | B9: 精河分输压气站 | C9: 140#-170# | D9: 173 | E9: 博州 | F9: 阿拉山口作业区
A10: 8 | B10: 6#阀室 | C10: 171#-202# | D10: 205 | E10: 博州 | F10: 阿拉山口作业区
A11: 9 | B11: 7#阀室 | C11: 203#-226# | D11: 230 | E11: 博州 | F11: 阿拉山口作业区
A12: 10 | B12: 8#阀室 | C12: 227#-254# | D12: 259 | E12: 博州 | F12: 阿拉山口作业区
A13: 11 | B13: 9#阀室 | C13: 255#-282# | D13: 287 | E13: 博州 | F13: 阿拉山口作业区
A14: 12 | B14: 10#阀室 | C14: 283#-310# | D14: 309 | E14: 乌苏市古尔图镇 | F14: 独山子作业区
A15: 13 | B15: 乌苏压气站 | C15: 311#-345# | D15: 344 | E15: 乌苏市四棵树镇 | F15: 独山子作业区
A16: 14 | B16: 11#阀室 | C16: 346#-372# | D16: 372 | E16: 乌苏市西大沟镇 | F16: 独山子作业区
A17: 15 | B17: 奎屯分输站 | C17: 373#-402# | D17: 402 | E17: 奎屯市奎独经济技术开发区 | F17: 独山子作业区
... A83: 81 | B83: 67#阀室 | C83: 2289#-2319# | D83: 2319.149 | E83: 白银市景泰县漫水滩乡 | F83: 古浪作业区
A84: 82 | B84: 68#阀室
A85: 83 | B85: 69#阀室
A86: 84 | B86: 70#阀室
A87: 85 | B87: 71#阀室
A88: 86 | B88: 中卫联络站 | D88: =D81+150 -> 2408.067

Sheet 西三线
A1: 西三线站场、阀室与里程桩对应表
A2: 序号 | B2: 站场/阀室名称 | C2: 桩号（阴保桩）前一阀室后一桩号-本阀室前一桩号 | D2: 里程/km | E2: 所在行政区域 | F2: 所属作业区 | G2: 外径 | H2: 壁厚 | I2: 内径 | J2: 管容
A3: 1 | B3: 霍尔果斯首站 | C3: 0# | D3: 0 | E3: 霍城县 | F3: 霍尔果斯作业区 | G3: 1219 | H3: 18.4 | I3: 1182.2 | J3: =1000*3.14*(I3/2/1000)*(I3/2/1000) -> 1097.1135
A4: 2 | B4: 1#阀室 | C4: 0#-30#+250m | D4: 30 | E4: 霍城县 | F4: 霍尔果斯作业区
A5: 3 | B5: 2#阀室 | C5: 31#-47#+200m | D5: 46 | E5: 霍城县 | F5: 霍尔果斯作业区
A6: 4 | B6: 3#阀室 | C6: 48#-75# | D6: 75 | E6: 霍城县 | F6: 霍尔果斯作业区
A7: 5 | B7: 4#阀室 | C7: 76#-103# | D7: 106 | E7: 博州 | F7: 阿拉山口作业区
A8: 6 | B8: 5#阀室 | C8: 104#-139# | D8: 142 | E8: 博州 | F8: 阿拉山口作业区
A9: 7 | B9: 精河分输压气站 | C9: 140#-169# | D9: 173 | E9: 博州 | F9: 阿拉山口作业区
A10: 8 | B10: 6#阀室 | C10: 170#-202# | D10: 205 | E10: 博州 | F10: 阿拉山口作业区
A11: 9 | B11: 7#阀室 | C11: 203#-226# | D11: 230 | E11: 博州 | F11: 阿拉山口作业区
A12: 10 | B12: 8#阀室 | C12: 227#-254# | D12: 259 | E12: 博州 | F12: 阿拉山口作业区
A13: 11 | B13: 9#阀室 | C13: 255#-282# | D13: 287 | E13: 博州 | F13: 阿拉山口作业区
A14: 12 | B14: 10#阀室 | C14: 283#-359# | D14: 311 | E14: 乌苏市古尔图镇 | F14: 独山子作业区
A15: 13 | B15: 乌苏压气站 | C15: 360#-395# | D15: 345 | E15: 乌苏市四棵树镇 | F15: 独山子作业区
... A42: 41 | B42: 哈密分输站 | C42: 1169#-1200# | D42: 1175.92 | E42: 哈密市 | F42: 了墩作业区
A43: 42 | B43: 35#阀室 | D43: 1207.1 | E43: 哈密市 | F43: 烟墩作业区
A44: 43 | B44: 烟墩压气站 | D44: 1234.1 | E44: 哈密市 | F44: 烟墩作业区
A45: 44 | B45: 36#阀室 | D45: 1259.07 | E45: 哈密市 | F45: 烟墩作业区
A46: 45 | B46: 37#阀室 | D46: 1287.04 | E46: 哈密市 | F46: 烟墩作业区
A47: 46 | B47: 38#阀室 | D47: 1313.1 | E47: 哈密市 | F47: 烟墩作业区
A48: 47 | B48: 39#阀室 | D48: 1337.2 | E48: 哈密市 | F48: 烟墩作业区
A49: 49 | B49: 39#阀室 | D49: 1328 | E49: 哈密市 | F49: 烟墩作业区
A50: 50 | B50: 红柳联络压气站 | C50: 1358#-1391# | D50: 1350 | E50: 酒泉市 | F50: 红柳作业区
A51: 51 | B51: 40#阀室 | C51: 1392#-1420# | D51: 1398 | E51: 酒泉市 | F51: 红柳作业区
A52: 52 | B52: 41#阀室 | C52: 1421#-1458# | D52: 1433 | E52: 酒泉市 | F52: 红柳作业区
A53: 53 | B53: 42#阀室 | C53: 1459#-1493# | D53: 1466 | E53: 酒泉市 | F53: 红柳作业区
A54: 54 | B54: 43#阀室 | C54: 1494#-1523# | D54: 1496.4 | E54: 甘肃省酒泉市瓜州县 | F54: 瓜州作业区
A55: 55 | B55: 44#阀室 | C55: 1524#-1558# | D55: 1527.3 | E55: 甘肃省酒泉市瓜州县布隆吉乡 | F55: 瓜州作业区
A56: 56 | B56: 瓜州压气站 | C56: 1559#-1592# | D56: 1548.5 | E56: 甘肃省酒泉市瓜州县腰站子乡 | F56: 瓜州作业区
A57: 57 | B57: 45#阀室 | C57: 1593#-1627# | D57: 1590.303 | E57: 玉门市柳河乡戈壁 | F57: 玉门作业区
A58: 58 | B58: 46#阀室 | C58: 1628#-1664+1# | D58: 1623.132 | E58: 玉门市赤金镇戈壁 | F58: 玉门作业区
A59: 59 | B59: 47#阀室 | C59: 1665#-1695# | D59: 1651.909 | E59: 玉门市赤金镇戈壁 | F59: 玉门作业区
A60: 60 | B60: 48#阀室 | C60: 1696#-1722# | D60: 1678.408 | E60: 玉门市清泉乡戈壁 | F60: 玉门作业区
A61: 61 | B61: 49#阀室 | C61: 1666#-1691# | D61: 1691.6 | E61: 嘉峪关市黑山湖砖厂 | F61: 酒泉作业区
... A83: 83 | B83: 67#阀室 | C83: 2289#-2319# | D83: 2065 | E83: 白银市景泰县漫水滩乡 | F83: 古浪作业区

Sheet 西四线
A1: 序号 | B1: 站场 | C1: 里程
A2: 1 | B2: 红柳压气站 | C2: 55.2
A3: 2 | B3: 19# | C3: 87.2
A4: 3 | B4: 20# | C4: 118.6
A5: 4 | B5: 21# | C5: 137.7
A6: 5 | B6: 22# | C6: 157
A7: 6 | B7: 23# | C7: 189
A8: 7 | B8: 24# | C8: 220.7
A9: 8 | B9: 瓜州压气站 | C9: 252.7
A10: 9 | B10: 25# | C10: 269.6
A11: 10 | B11: 26# | C11: 291.9
A12: 11 | B12: 27# | C12: 307.6
A13: 12 | B13: 28# | C13: 332.2
... A49: 48 | B49: 中卫联络站 | C49: 1197.4

Sheet 涩宁兰一线
A1: 涩一线站场、阀室与里程桩对应表
A2: 序号 | B2: 站场/阀室名称 | C2: 桩号（阴保桩）前一阀室后一桩号-本阀室前一桩号 | D2: 里程/km | E2: 所在行政区域 | F2: 所属作业区 | G2: 备注 | H2: 外径 | I2: 壁厚 | J2: 内径 | K2: 管容
A3: 1 | B3: 涩北压气站 | D3: 0 | E3: 格尔木市 | F3: 涩北压气首站 | H3: 660 | I3: 7.1 | J3: =H3-I3-I3 -> 645.8 | K3: =1000*3.14*(J3/2/1000)*(J3/2/1000) -> 327.39025
A4: 2 | B4: 1#阀室 | C4: 0-#29# | D4: 30.825 | E4: 格尔木市 | F4: 涩北压气首站
A5: 3 | B5: 2#阀室 | C5: 30#-58# | D5: 59.725 | E5: 大柴旦镇 | F5: 涩北压气首站
A6: 4 | B6: 3#阀室 | C6: 59#-87# | D6: 88.163 | E6: 大柴旦镇 | F6: 涩北压气首站
A7: 5 | B7: 4#阀室 | C7: 88#-109# | D7: 110.79 | E7: 大柴旦镇 | F7: 涩北压气首站
A8: 6 | B8: 5#阀室 | C8: 110#-113# | D8: 112.9 | E8: 大柴旦镇 | F8: 涩北压气首站
A9: 7 | B9: 6#阀室 | C9: 114#-130# | D9: 131.907 | E9: 大柴旦镇 | F9: 涩北压气首站
A10: 8 | B10: 7#阀室 | C10: 131#-150# | D10: 151.024 | E10: 大柴旦镇 | F10: 涩北压气首站
A11: 9 | B11: 羊肠子沟站 | C11: 151#-169# | D11: 170.141 | E11: 大柴旦镇 | F11: 德令哈作业区
A12: 10 | B12: 8#阀室 | C12: 170#-198# | D12: 199.372 | E12: 德令哈市 | F12: 德令哈作业区
A13: 11 | B13: 9#阀室 | C13: 199#-225# | D13: 225.99 | E13: 德令哈市 | F13: 德令哈作业区
A14: 12 | B14: 10#阀室 | C14: 226#-257# | D14: 257.836 | E14: 德令哈市 | F14: 德令哈作业区
A15: 13 | B15: 11#阀室 | C15: 258#-286# | D15: 287.858 | E15: 德令哈市 | F15: 德令哈作业区
... A43: 41 | B43: 兰州分输末站 | C43: 908#-930# | D43: 921.59 | E43: 兰州市西固区 | F43: 兰州输气末站
A44: 42
A45: 43
A46: 44
A47: 45
A48: 46
A49: 47
A50: 48
A51: 49
A52: 50
A53: 51
A54: 52
A55: 53
... A88: 86

Sheet 涩宁兰复线
A1: 涩复线站场、阀室与里程桩对应表
A2: 序号 | B2: 站场/阀室名称 | C2: 桩号（阴保桩）前一阀室后一桩号-本阀室前一桩号 | D2: 里程/km | E2: 所在行政区域 | F2: 所属作业区 | G2: 备注 | H2: 外径 | I2: 壁厚 | J2: 内径 | K2: 管容
A3: 1 | B3: 涩北压气站 | D3: 0 | E3: 格尔木市 | F3: 涩北压气首站 | H3: 660 | I3: 7.1 | J3: =H3-I3-I3 -> 645.8 | K3: =1000*3.14*(J3/2/1000)*(J3/2/1000) -> 327.39025
A4: 2 | B4: 1#阀室 | C4: 0#-29# | D4: 31.2 | E4: 大柴旦镇 | F4: 涩北压气首站
A5: 3 | B5: 2#阀室 | C5: 30#-58# | D5: 60.7 | E5: 大柴旦镇 | F5: 涩北压气首站
A6: 4 | B6: 3#阀室 | C6: 59#-86# | D6: 89.6 | E6: 大柴旦镇 | F6: 涩北压气首站
A7: 5 | B7: 4#阀室 | C7: 87#-114# | D7: 115 | E7: 大柴旦镇 | F7: 涩北压气首站
A8: 6 | B8: 5#阀室 | C8: 115#-144# | D8: 144.3 | E8: 大柴旦镇 | F8: 涩北压气首站
A9: 7 | B9: 羊肠子沟站 | C9: 145#-169# | D9: 173.2 | E9: 大柴旦镇 | F9: 德令哈作业区
A10: 8 | B10: 6#阀室 | C10: 170#-198# | D10: 201.8 | E10: 青海省 | F10: 德令哈作业区
A11: 9 | B11: 7#阀室 | C11: 199#-225# | D11: 229.3 | E11: 青海省 | F11: 德令哈作业区
A12: 10 | B12: 8#阀室 | C12: 226#-257# | D12: 261.9 | E12: 青海省 | F12: 德令哈作业区
A13: 11 | B13: 9#阀室 | C13: 258#-284# | D13: 288.7 | E13: 青海省 | F13: 德令哈作业区
A14: 12 | B14: 10#阀室 | C14: 285#-291# | D14: 296.7 | E14: 德令哈市 | F14: 德令哈作业区
A15: 13 | B15: 11#阀室 | C15: 292#-320# | D15: 320.7 | E15: 青海省 | F15: 德令哈作业区
... A43: 41 | B43: 35#阀室 | C43: 907#-910# | D43: 921.4 | E43: 兰州市 | F43: 兰州输气末站
A44: 42
A45: 43
A46: 44
A47: 45
A48: 46
A49: 47
A50: 48
A51: 49
A52: 50
A53: 51
A54: 52
A55: 53
... A88: 86

Sheet 压缩因子
A1: 压力与压缩因子对照表 | H1: 压缩因子计算
A2: 压力(MPa) | B2: 压缩因子 | C2: 压力(MPa) | D2: 压缩因子 | E2: 压力(MPa) | F2: 压缩因子 | H2: 压力段 | I2: 压力(MPa) | J2: 压缩因子 | K2: 压力(MPa) | L2: 压缩因子 | M2: 压力(MPa) | N2: 压缩因子
A3: 2 | B3: 0.9532 | C3: 5 | D3: 0.8903 | E3: 8 | F3: 0.8377 | H3: 0～1 | I3: 0 | J3: 1 | K3: 1 | L3: 0.9766 | M3: 0.23 | N3: =IF(M3="","",(L3-J3)/(K3-I3)*(M3-I3)+J3) -> 0.994618
A4: 2.5 | B4: 0.9423 | C4: 5.5 | D4: 0.8806 | E4: 8.5 | F4: 0.8305 | H4: 1～2 | I4: 1 | J4: 0.9766 | K4: 2 | L4: 0.9532 | N4: =IF(M4="","",(L4-J4)/(K4-I4)*(M4-I4)+J4)
A5: 3 | B5: 0.9315 | C5: 6 | D5: 0.8713 | E5: 9 | F5: 0.8228 | H5: 2～2.5 | I5: 2 | J5: 0.9532 | K5: 2.5 | L5: 0.9423 | N5: =IF(M5="","",(L5-J5)/(K5-I5)*(M5-I5)+J5)
A6: 3.5 | B6: 0.9209 | C6: 6.5 | D6: 0.8623 | E6: 9.5 | F6: 0.8177 | H6: 2.5～3 | I6: 2.5 | J6: 0.9423 | K6: 3 | L6: 0.9315 | N6: =IF(M6="","",(L6-J6)/(K6-I6)*(M6-I6)+J6)
A7: 4 | B7: 0.9105 | C7: 7 | D7: 0.8537 | E7: 9.9 | F7: 0.8132 | H7: 3～3.5 | I7: 3 | J7: 0.9315 | K7: 3.5 | L7: 0.9209 | M7: 3.42 | N7: =IF(M7="","",(L7-J7)/(K7-I7)*(M7-I7)+J7) -> 0.922596
A8: 4.5 | B8: 0.9003 | C8: 7.5 | D8: 0.8455 | H8: 3.5～4 | I8: 3.5 | J8: 0.9209 | K8: 4 | L8: 0.9105 | N8: =IF(M8="","",(L8-J8)/(K8-I8)*(M8-I8)+J8)
A9: 0 | B9: 1 | H9: 4～4.5 | I9: 4 | J9: 0.9105 | K9: 4.5 | L9: 0.9003 | M9: 4.21 | N9: =IF(M9="","",(L9-J9)/(K9-I9)*(M9-I9)+J9) -> 0.906216
H10: 4.5～5 | I10: 4.5 | J10: 0.9003 | K10: 5 | L10: 0.8903 | M10: 4.65 | N10: =IF(M10="","",(L10-J10)/(K10-I10)*(M10-I10)+J10) -> 0.8973
H11: 5～5.5 | I11: 5 | J11: 0.8903 | K11: 5.5 | L11: 0.8806 | M11: 8.26 | N11: =IF(M11="","",(L11-J11)/(K11-I11)*(M11-I11)+J11) -> 0.827056
H12: 5.5～6 | I12: 5.5 | J12: 0.8806 | K12: 6 | L12: 0.8713 | N12: =IF(M12="","",(L12-J12)/(K12-I12)*(M12-I12)+J12)
H13: 6～6.5 | I13: 6 | J13: 0.8713 | K13: 6.5 | L13: 0.8623 | M13: 6.18 | N13: =IF(M13="","",(L13-J13)/(K13-I13)*(M13-I13)+J13) -> 0.86806
H14: 6.5～7 | I14: 6.5 | J14: 0.8623 | K14: 7 | L14: 0.8537 | M14: 6.88 | N14: =IF(M14="","",(L14-J14)/(K14-I14)*(M14-I14)+J14) -> 0.855764
H15: 7～7.5 | I15: 7 | J15: 0.8537 | K15: 7.5 | L15: 0.8455 | M15: 7.11 | N15: =IF(M15="","",(L15-J15)/(K15-I15)*(M15-I15)+J15) -> 0.851896
H16: 7.5～8 | I16: 7.5 | J16: 0.8455 | K16: 8 | L16: 0.8377 | M16: 7.59 | N16: =IF(M16="","",(L16-J16)/(K16-I16)*(M16-I16)+J16) -> 0.844096
H17: 8～8.5 | I17: 8 | J17: 0.8377 | K17: 8.5 | L17: 0.8305 | M17: 8 | N17: =IF(M17="","",(L17-J17)/(K17-I17)*(M17-I17)+J17) -> 0.8377
H18: 8.5～9 | I18: 8.5 | J18: 0.8305 | K18: 9 | L18: 0.8228 | M18: 8.611 | N18: =IF(M18="","",(L18-J18)/(K18-I18)*(M18-I18)+J18) -> 0.8287906
H19: 9～9.5 | I19: 9 | J19: 0.8228 | K19: 9.5 | L19: 0.8177 | M19: 9.28 | N19: =IF(M19="","",(L19-J19)/(K19-I19)*(M19-I19)+J19) -> 0.819944
H20: 9.5～9.9 | I20: 9.5 | J20: 0.8177 | K20: 9.9 | L20: 0.8132 | M20: 9.55 | N20: =IF(M20="","",(L20-J20)/(K20-I20)*(M20-I20)+J20) -> 0.8171375
H21: 9.9～10 | I21: 9.9 | J21: 0.8132 | K21: 10 | L21: 0.8128 | M21: 9.92 | N21: =IF(M21="","",(L21-J21)/(K21-I21)*(M21-I21)+J21) -> 0.81312
H22: 10~10.5 | I22: 10 | J22: 0.8128 | K22: 10.5 | L22: 0.8063 | M22: 10.15 | N22: =IF(M22="","",(L22-J22)/(K22-I22)*(M22-I22)+J22) -> 0.81085
H23: 10.5~11 | I23: 10.5 | J23: 0.8063 | K23: 11 | L23: 0.8003 | M23: 10.94 | N23: =IF(M23="","",(L23-J23)/(K23-I23)*(M23-I23)+J23) -> 0.80102
N24: =IF(M24="","",(L24-J24)/(K24-I24)*(M24-I24)+J24)

Sheet 油品分输时间
A1: 分输量 | B1: 分输瞬时量 | C1: 开始分输时间 | D1: 结束分输时间
A2: 3000 | B2: 70 | C2: 45702.507 | D2: =(A2/B2/24)+C2 -> 45704.293
